<?xml version="1.0" ?>
<!-- =================================================================================== -->
<!-- |    This document was autogenerated by xacro from robot.urdf.xacro               | -->
<!-- |    EDITING THIS FILE BY HAND IS NOT RECOMMENDED                                 | -->
<!-- =================================================================================== -->
<robot name="diff_drive_robot">
  <!-- Specify some standard inertial calculations https://en.wikipedia.org/wiki/List_of_moments_of_inertia -->
  <!-- These make use of xacro's mathematical functionality -->
  <!-- Base link -->
  <link name="base_link"/>
  <!-- Chassis link -->
  <joint name="chassis_joint" type="fixed">
    <parent link="base_link"/>
    <child link="chassis"/>
    <origin xyz="0 0 0.34199999999999997"/>
  </joint>
  <link name="chassis">
    <visual>
      <origin xyz="0 0 0"/>
      <geometry>
        <box size="0.7 0.52 0.582"/>
      </geometry>
      <material name="chassis_material">
        <color rgba="0.40 0.23 0.72 1.0"/>
      </material>
    </visual>
    <collision>
      <origin xyz="0 0 0"/>
      <geometry>
        <box size="0.7 0.52 0.582"/>
      </geometry>
    </collision>
    <inertial>
      <origin rpy="0 0 0" xyz="0 0 0"/>
      <mass value="0.5"/>
      <inertia ixx="0.025380166666666665" ixy="0.0" ixz="0.0" iyy="0.03453016666666666" iyz="0.0" izz="0.03168333333333333"/>
    </inertial>
  </link>
  <!-- Left wheel (centered along length) -->
  <joint name="left_wheel_joint" type="continuous">
    <parent link="base_link"/>
    <child link="left_wheel"/>
    <origin rpy="-1.5707963267948966 0 0" xyz="0 0.2965 0.1"/>
    <axis xyz="0 0 1"/>
  </joint>
  <link name="left_wheel">
    <visual>
      <geometry>
        <cylinder length="0.04" radius="0.1"/>
      </geometry>
      <material name="wheel_material">
        <color rgba="0.0 0.0 0.0 1.0"/>
      </material>
    </visual>
    <collision>
      <geometry>
        <cylinder length="0.04" radius="0.1"/>
      </geometry>
    </collision>
    <inertial>
      <origin rpy="0 0 0" xyz="0 0 0"/>
      <mass value="0.1"/>
      <inertia ixx="0.00026333333333333336" ixy="0.0" ixz="0.0" iyy="0.00026333333333333336" iyz="0.0" izz="0.0005000000000000001"/>
    </inertial>
  </link>
  <!-- Right wheel (centered along length) -->
  <joint name="right_wheel_joint" type="continuous">
    <parent link="base_link"/>
    <child link="right_wheel"/>
    <origin rpy="1.5707963267948966 0 0" xyz="0 -0.2965 0.1"/>
    <axis xyz="0 0 -1"/>
  </joint>
  <link name="right_wheel">
    <visual>
      <geometry>
        <cylinder length="0.04" radius="0.1"/>
      </geometry>
      <material name="wheel_material">
        <color rgba="0.0 0.0 0.0 1.0"/>
      </material>
    </visual>
    <collision>
      <geometry>
        <cylinder length="0.04" radius="0.1"/>
      </geometry>
    </collision>
    <inertial>
      <origin rpy="0 0 0" xyz="0 0 0"/>
      <mass value="0.1"/>
      <inertia ixx="0.00026333333333333336" ixy="0.0" ixz="0.0" iyy="0.00026333333333333336" iyz="0.0" izz="0.0005000000000000001"/>
    </inertial>
  </link>
  <!-- Front castor wheel (same height as main wheels) -->
  <joint name="front_castor_wheel_joint" type="fixed">
    <parent link="base_link"/>
    <child link="front_castor_wheel"/>
    <origin xyz="0.299 0 0.051"/>
  </joint>
  <link name="front_castor_wheel">
    <visual>
      <geometry>
        <sphere radius="0.051"/>
      </geometry>
      <material name="castor_material">
        <color rgba="0.62 0.62 0.62 1.0"/>
      </material>
    </visual>
    <collision>
      <geometry>
        <sphere radius="0.051"/>
      </geometry>
    </collision>
    <inertial>
      <origin rpy="0 0 0" xyz="0 0 0"/>
      <mass value="0.1"/>
      <inertia ixx="0.00010404" ixy="0.0" ixz="0.0" iyy="0.00010404" iyz="0.0" izz="0.00010404"/>
    </inertial>
  </link>
  <!-- Rear castor wheel (same height as main wheels) -->
  <joint name="rear_castor_wheel_joint" type="fixed">
    <parent link="base_link"/>
    <child link="rear_castor_wheel"/>
    <origin xyz="-0.299 0 0.051"/>
  </joint>
  <link name="rear_castor_wheel">
    <visual>
      <geometry>
        <sphere radius="0.051"/>
      </geometry>
      <material name="castor_material">
        <color rgba="0.62 0.62 0.62 1.0"/>
      </material>
    </visual>
    <collision>
      <geometry>
        <sphere radius="0.051"/>
      </geometry>
    </collision>
    <inertial>
      <origin rpy="0 0 0" xyz="0 0 0"/>
      <mass value="0.1"/>
      <inertia ixx="0.00010404" ixy="0.0" ixz="0.0" iyy="0.00010404" iyz="0.0" izz="0.00010404"/>
    </inertial>
  </link>
  <!-- Gazebo Parameters -->
  <gazebo reference="chassis_link">
    <mu1>1.0</mu1>
    <mu2>1.0</mu2>
  </gazebo>
  <gazebo reference="right_wheel">
    <mu1>1.0</mu1>
    <mu2>1.0</mu2>
  </gazebo>
  <gazebo reference="left_wheel">
    <mu1>1.0</mu1>
    <mu2>1.0</mu2>
  </gazebo>
  <gazebo reference="front_castor_wheel">
    <mu1>0.000001</mu1>
    <mu2>0.000001</mu2>
  </gazebo>
  <gazebo reference="rear_castor_wheel">
    <mu1>0.000001</mu1>
    <mu2>0.000001</mu2>
  </gazebo>
  <gazebo>
    <plugin filename="gz-sim-diff-drive-system" name="gz::sim::systems::DiffDrive">
      <right_joint>right_wheel_joint</right_joint>
      <left_joint>left_wheel_joint</left_joint>
      <wheel_separation>0.593</wheel_separation>
      <wheel_diameter>0.2</wheel_diameter>
      <max_linear_acceleration>10</max_linear_acceleration>
      <topic>cmd_vel</topic>
      <odom_topic>odom</odom_topic>
      <frame_id>odom</frame_id>
      <child_frame_id>base_link</child_frame_id>
      <odom_publisher_frequency>100</odom_publisher_frequency>
      <tf_topic>/tf</tf_topic>
    </plugin>
    <plugin filename="gz-sim-joint-state-publisher-system" name="gz::sim::systems::JointStatePublisher">
      <topic>joint_states</topic>
      <joint_name>right_wheel_joint</joint_name>
      <joint_name>left_wheel_joint</joint_name>
    </plugin>
  </gazebo>
  <joint name="laser_joint" type="fixed">
    <parent link="chassis"/>
    <child link="laser_frame"/>
    <origin rpy="0 0 0" xyz="0.1 0 0.291"/>
  </joint>
  <link name="laser_frame">
    <visual>
      <origin xyz="0 0 0"/>
      <geometry>
        <cylinder length="0.04" radius="0.05"/>
      </geometry>
      <material name="laser_material">
        <color rgba="0.13 0.13 0.13 1.0"/>
      </material>
    </visual>
    <collision>
      <origin xyz="0 0 0"/>
      <geometry>
        <cylinder length="0.04" radius="0.05"/>
      </geometry>
    </collision>
    <inertial>
      <origin rpy="0 0 0" xyz="0 0 0"/>
      <mass value="0.1"/>
      <inertia ixx="7.583333333333335e-05" ixy="0.0" ixz="0.0" iyy="7.583333333333335e-05" iyz="0.0" izz="0.00012500000000000003"/>
    </inertial>
  </link>
  <!-- 2D Lidar New Gazebo Sensor Plugin  -->
  <gazebo reference="laser_frame">
    <sensor name="laser" type="gpu_lidar">
      <pose> 0 0 0 0 0 0 </pose>
      <always_on>true</always_on>
      <visualize>true</visualize>
      <update_rate>10</update_rate>
      <topic>scan</topic>
      <gz_frame_id>laser_frame</gz_frame_id>
      <lidar>
        <scan>
          <horizontal>
            <samples>360</samples>
            <min_angle>-3.14</min_angle>
            <max_angle>3.14</max_angle>
          </horizontal>
        </scan>
        <range>
          <min>0.3</min>
          <max>12</max>
        </range>
      </lidar>
    </sensor>
  </gazebo>
</robot>
