<?xml version="1.0" ?>
<!-- =================================================================================== -->
<!-- |    This document was autogenerated by xacro from robot.urdf.xacro               | -->
<!-- |    EDITING THIS FILE BY HAND IS NOT RECOMMENDED                                 | -->
<!-- =================================================================================== -->
<robot name="diff_drive_robot">
  <!-- <xacro:property name="lidar"        value="$(env LIDAR_TYPE)"/>
    <xacro:property name="machine"      value="$(env MACHINE_TYPE)"/>

    <xacro:if value="${lidar in ['A1', 'A2', 'S2L', 'LD14P']}">
    </xacro:if>
    <xacro:if value="${machine == 'JetRover_Mecanum'}">
    </xacro:if> -->
  <!-- Specify some standard inertial calculations https://en.wikipedia.org/wiki/List_of_moments_of_inertia -->
  <!-- These make use of xacro's mathematical functionality -->
  <link name="base_footprint"/>
  <joint name="base_link_joint" type="fixed">
    <parent link="base_footprint"/>
    <child link="base_link"/>
    <origin xyz="0 0 0"/>
  </joint>
  <!-- Base link -->
  <link name="base_link"/>
  <!-- Chassis link -->
  <joint name="chassis_joint" type="fixed">
    <parent link="base_link"/>
    <child link="chassis"/>
    <origin xyz="0 0 0.346"/>
  </joint>
  <link name="chassis">
    <visual>
      <origin xyz="0 0 0"/>
      <geometry>
        <box size="0.7 0.52 0.582"/>
      </geometry>
      <material name="chassis_material">
        <color rgba="0.40 0.23 0.72 1.0"/>
      </material>
    </visual>
    <collision>
      <origin xyz="0 0 0"/>
      <geometry>
        <box size="0.7 0.52 0.582"/>
      </geometry>
    </collision>
    <inertial>
      <origin rpy="0 0 0" xyz="0 0 0"/>
      <mass value="0.5"/>
      <inertia ixx="0.025380166666666665" ixy="0.0" ixz="0.0" iyy="0.03453016666666666" iyz="0.0" izz="0.03168333333333333"/>
    </inertial>
  </link>
  <!-- Left wheel (centered along length) -->
  <joint name="left_wheel_joint" type="continuous">
    <parent link="base_link"/>
    <child link="left_wheel"/>
    <origin rpy="-1.5707963267948966 0 0" xyz="0 0.2965 0.1"/>
    <axis xyz="0 0 1"/>
  </joint>
  <link name="left_wheel">
    <visual>
      <geometry>
        <cylinder length="0.04" radius="0.1"/>
      </geometry>
      <material name="wheel_material">
        <color rgba="0.0 0.0 0.0 1.0"/>
      </material>
    </visual>
    <collision>
      <geometry>
        <cylinder length="0.04" radius="0.1"/>
      </geometry>
    </collision>
    <inertial>
      <origin rpy="0 0 0" xyz="0 0 0"/>
      <mass value="0.1"/>
      <inertia ixx="0.00026333333333333336" ixy="0.0" ixz="0.0" iyy="0.00026333333333333336" iyz="0.0" izz="0.0005000000000000001"/>
    </inertial>
  </link>
  <!-- Right wheel (centered along length) -->
  <joint name="right_wheel_joint" type="continuous">
    <parent link="base_link"/>
    <child link="right_wheel"/>
    <origin rpy="1.5707963267948966 0 0" xyz="0 -0.2965 0.1"/>
    <axis xyz="0 0 -1"/>
  </joint>
  <link name="right_wheel">
    <visual>
      <geometry>
        <cylinder length="0.04" radius="0.1"/>
      </geometry>
      <material name="wheel_material">
        <color rgba="0.0 0.0 0.0 1.0"/>
      </material>
    </visual>
    <collision>
      <geometry>
        <cylinder length="0.04" radius="0.1"/>
      </geometry>
    </collision>
    <inertial>
      <origin rpy="0 0 0" xyz="0 0 0"/>
      <mass value="0.1"/>
      <inertia ixx="0.00026333333333333336" ixy="0.0" ixz="0.0" iyy="0.00026333333333333336" iyz="0.0" izz="0.0005000000000000001"/>
    </inertial>
  </link>
  <!-- Front castor wheel (same height as main wheels) -->
  <joint name="front_castor_wheel_joint" type="fixed">
    <parent link="base_link"/>
    <child link="front_castor_wheel"/>
    <origin xyz="0.295 0 0.055"/>
  </joint>
  <link name="front_castor_wheel">
    <visual>
      <geometry>
        <sphere radius="0.055"/>
      </geometry>
      <material name="castor_material">
        <color rgba="0.62 0.62 0.62 1.0"/>
      </material>
    </visual>
    <collision>
      <geometry>
        <sphere radius="0.055"/>
      </geometry>
    </collision>
    <inertial>
      <origin rpy="0 0 0" xyz="0 0 0"/>
      <mass value="0.1"/>
      <inertia ixx="0.00012100000000000001" ixy="0.0" ixz="0.0" iyy="0.00012100000000000001" iyz="0.0" izz="0.00012100000000000001"/>
    </inertial>
  </link>
  <!-- Rear castor wheel (same height as main wheels) -->
  <joint name="rear_castor_wheel_joint" type="fixed">
    <parent link="base_link"/>
    <child link="rear_castor_wheel"/>
    <origin xyz="-0.295 0 0.055"/>
  </joint>
  <link name="rear_castor_wheel">
    <visual>
      <geometry>
        <sphere radius="0.055"/>
      </geometry>
      <material name="castor_material">
        <color rgba="0.62 0.62 0.62 1.0"/>
      </material>
    </visual>
    <collision>
      <geometry>
        <sphere radius="0.055"/>
      </geometry>
    </collision>
    <inertial>
      <origin rpy="0 0 0" xyz="0 0 0"/>
      <mass value="0.1"/>
      <inertia ixx="0.00012100000000000001" ixy="0.0" ixz="0.0" iyy="0.00012100000000000001" iyz="0.0" izz="0.00012100000000000001"/>
    </inertial>
  </link>
  <!-- Gazebo Parameters -->
  <gazebo reference="chassis_link">
    <mu1>1.0</mu1>
    <mu2>1.0</mu2>
  </gazebo>
  <gazebo reference="right_wheel">
    <mu1>1.0</mu1>
    <mu2>1.0</mu2>
  </gazebo>
  <gazebo reference="left_wheel">
    <mu1>1.0</mu1>
    <mu2>1.0</mu2>
  </gazebo>
  <gazebo reference="front_castor_wheel">
    <mu1>0.000001</mu1>
    <mu2>0.000001</mu2>
  </gazebo>
  <gazebo reference="rear_castor_wheel">
    <mu1>0.000001</mu1>
    <mu2>0.000001</mu2>
  </gazebo>
  <joint name="laser_joint" type="fixed">
    <parent link="chassis"/>
    <child link="laser_frame"/>
    <origin rpy="0 0 0" xyz="0.28 0 0.353"/>
  </joint>
  <link name="laser_frame">
    <visual>
      <origin xyz="0 0 0"/>
      <geometry>
        <cylinder length="0.04" radius="0.05"/>
      </geometry>
      <material name="laser_material">
        <color rgba="0.13 0.13 0.13 1.0"/>
      </material>
    </visual>
    <collision>
      <origin xyz="0 0 0"/>
      <geometry>
        <cylinder length="0.04" radius="0.05"/>
      </geometry>
    </collision>
    <inertial>
      <origin rpy="0 0 0" xyz="0 0 0"/>
      <mass value="0.1"/>
      <inertia ixx="7.583333333333335e-05" ixy="0.0" ixz="0.0" iyy="7.583333333333335e-05" iyz="0.0" izz="0.00012500000000000003"/>
    </inertial>
  </link>
  <!-- 2D Lidar New Gazebo Sensor Plugin  -->
  <gazebo reference="laser_frame">
    <sensor name="laser" type="gpu_lidar">
      <pose> 0 0 0 0 0 0 </pose>
      <always_on>true</always_on>
      <visualize>true</visualize>
      <update_rate>10</update_rate>
      <topic>scan</topic>
      <gz_frame_id>laser_frame</gz_frame_id>
      <lidar>
        <scan>
          <horizontal>
            <samples>360</samples>
            <min_angle>-3.14</min_angle>
            <max_angle>3.14</max_angle>
          </horizontal>
        </scan>
        <range>
          <min>0.3</min>
          <max>12</max>
        </range>
      </lidar>
    </sensor>
  </gazebo>
  <link name="imu_link">
    <visual>
      <origin rpy="0 0 0" xyz="0 0 0"/>
      <geometry>
        <box size="0.03899 0.03785 0.01338"/>
      </geometry>
      <material name="imu_black">
        <color rgba="0.1 0.1 0.1 1"/>
      </material>
    </visual>
    <inertial>
      <mass value="0.031"/>
      <origin rpy="0 0 0" xyz="0.34 0 0"/>
      <inertia ixx="4.163421158333333e-06" ixy="0.0" ixz="0.0" iyy="4.389714958333333e-06" iyz="0.0" izz="7.6281767166666665e-06"/>
    </inertial>
  </link>
  <joint name="imu_joint" type="fixed">
    <parent link="chassis"/>
    <child link="imu_link"/>
    <origin rpy="0 0 0" xyz="0.34 0 -0.15599999999999997"/>
  </joint>
  <gazebo reference="imu_link">
    <material>
      <ambient>0.1 0.1 0.1 1</ambient>
      <diffuse>0.1 0.1 0.1 1</diffuse>
      <specular>0.1 0.1 0.1 1</specular>
    </material>
    <sensor name="imu_sensor" type="imu">
      <topic>imu/data</topic>
      <update_rate>15.0</update_rate>
      <always_on>True</always_on>
      <visualize>False</visualize>
      <gz_frame_id>imu_link</gz_frame_id>
    </sensor>
  </gazebo>
  <link name="camera_depth_optical_frame">
    <visual>
      <origin rpy="1.5707963267948966 0.0 1.5707963267948966" xyz="0 0 0"/>
      <geometry>
        <box size="0.02 0.08 0.02"/>
      </geometry>
      <material name="aluminum">
        <color rgba="0.5 0.5 0.5 1"/>
      </material>
    </visual>
    <inertial>
      <mass value="0.072"/>
      <origin rpy="0 0 0" xyz="0 0 0"/>
      <inertia ixx="0.003881243" ixy="0.0" ixz="0.0" iyy="0.00049894" iyz="0.0" izz="0.003879257"/>
    </inertial>
  </link>
  <joint name="cam_1_joint" type="fixed">
    <parent link="chassis"/>
    <child link="camera_depth_optical_frame"/>
    <origin rpy="0 -0.50 0" xyz="0.105 0 0.05"/>
  </joint>
  <!-- <joint name="${prefix}${camera_name}_depth_joint" type="fixed">
      <origin xyz="${depth_frame_xyz_offset}" rpy="${depth_frame_rpy_offset}"/>
      <parent link="${prefix}${camera_name}_link"/>
      <child link="${prefix}${camera_name}_depth_frame" />
    </joint>
    <link name="${prefix}${camera_name}_depth_frame"/>

    <joint name="${prefix}${camera_name}_depth_optical_joint" type="fixed">
      <origin xyz="${optical_xyz_offset}" rpy="${optical_rpy_offset}" />
      <parent link="${prefix}${camera_name}_depth_frame" />
      <child link="${prefix}${camera_name}_depth_optical_frame" />
    </joint>
    <link name="${prefix}${camera_name}_depth_optical_frame"/>

    <joint name="${prefix}${camera_name}_infra1_joint" type="fixed">
      <origin xyz="${infra1_xyz_offset}" rpy="${infra1_rpy_offset}" />
      <parent link="${prefix}${camera_name}_link" />
      <child link="${prefix}${camera_name}_infra1_frame" />
    </joint>
    <link name="${prefix}${camera_name}_infra1_frame"/>

    <joint name="${prefix}${camera_name}_infra1_optical_joint" type="fixed">
      <origin xyz="${optical_xyz_offset}" rpy="${optical_rpy_offset}" />
      <parent link="${prefix}${camera_name}_infra1_frame" />
      <child link="${prefix}${camera_name}_infra1_optical_frame" />
    </joint>
    <link name="${prefix}${camera_name}_infra1_optical_frame"/>

    <joint name="${prefix}${camera_name}_infra2_joint" type="fixed">
      <origin xyz="${infra2_xyz_offset}" rpy="${infra2_rpy_offset}" />
      <parent link="${prefix}${camera_name}_link" />
      <child link="${prefix}${camera_name}_infra2_frame" />
    </joint>
    <link name="${prefix}${camera_name}_infra2_frame"/>

    <joint name="${prefix}${camera_name}_infra2_optical_joint" type="fixed">
      <origin xyz="${optical_xyz_offset}" rpy="${optical_rpy_offset}" />
      <parent link="${prefix}${camera_name}_infra2_frame" />
      <child link="${prefix}${camera_name}_infra2_optical_frame" />
    </joint>
    <link name="${prefix}${camera_name}_infra2_optical_frame"/>

    <joint name="${prefix}${camera_name}_color_joint" type="fixed">
      <origin xyz="${color_xyz_offset}" rpy="${color_rpy_offset}" />
      <parent link="${prefix}${camera_name}_link" />
      <child link="${prefix}${camera_name}_color_frame" />
    </joint>
    <link name="${prefix}${camera_name}_color_frame"/>

    <joint name="${prefix}${camera_name}_color_optical_joint" type="fixed">
      <origin xyz="${optical_xyz_offset}" rpy="${optical_rpy_offset}" />
      <parent link="${prefix}${camera_name}_color_frame" />
      <child link="${prefix}${camera_name}_color_optical_frame" />
    </joint>
    <link name="${prefix}${camera_name}_color_optical_frame"/> -->
  <gazebo reference="camera_depth_optical_frame">
    <sensor name="dabai_dcw" type="rgbd_camera">
      <camera>
        <horizontal_fov>1.5184</horizontal_fov>
        <image>
          <width>424</width>
          <height>240</height>
        </image>
        <clip>
          <near>0.05</near>
          <far>1.5</far>
        </clip>
      </camera>
      <always_on>1</always_on>
      <gz_frame_id>cam_1_link</gz_frame_id>
      <topic>cam_1</topic>
      <update_rate>2</update_rate>
      <visualize>True</visualize>
    </sensor>
  </gazebo>
</robot>
